Workbook

Sheet Read Me
A1: Arm Holdings IPO Valuation & Strategy Analysis — Phase 2 Workbook
A4: Purpose
A5: Phase 2 establishes the historical financial base for the Arm IPO case study. It covers FY2022–FY2026 actual results, revenue mix, margins, cash flow, and a balance-sheet snapshot. Later phases will add comparable-company valuation, IPO pricing analysis, post-IPO performance, and strategy.
A9: Model Conventions
A10: Blue font | B10: Hardcoded / source-reported historical inputs
A11: Black font | B11: Formulas and calculated metrics
A12: Green font | B12: Cross-sheet links (used in later phases)
A13: Units | B13: $ in millions except per-share data and percentages
A14: Fiscal year | B14: Arm fiscal year ends March 31
A16: Phase Map
A17: Phase | B17: Status | C17: Output
A18: 1 — IPO Research | B18: Complete | C18: Transaction facts, business model, risks, peer universe
A19: 2 — Historical Financials | B19: Complete | C19: Historical financials + IPO-date snapshot
A20: 3 — Comparable Companies | B20: Complete | C20: Six-peer CCA populated with 9/13/2023 prices and pre-IPO LTM financials
A21: 4 — IPO Valuation | B21: Complete | C21: Comp-implied valuation range and IPO pricing conclusion
A22: 5 — Post-IPO Performance | B22: Complete | C22: Operating validation, market milestones, Q1 FY2027 check-in
A23: 6 — Strategy & Risks | B23: Complete | C23: Growth-driver and risk framework
A24: 7 — Executive Summary
A28: Project status: analytical workbook complete. The final workbook now contains historical financials, IPO snapshot, six-peer CCA, comp-implied valuation range, post-IPO performance, strategy/risk analysis, and executive summary. A report, presentation, and GitHub README should accompany this workbook in the public portfolio.

Sheet Historical Financials
A1: Arm Holdings plc — Historical Financials
A3: $ in millions except per-share data | Fiscal year ended March 31
B5: FY2022A | C5: FY2023A | D5: FY2024A | E5: FY2025A | F5: FY2026A | G5: Source
A7: Income Statement
A8: License & Other Revenue | B8: 1141 | C8: 1004 | D8: 1431 | E8: 1839 | F8: 2307 | G8: S1/S2/S3
A9: Royalty Revenue | B9: 1562 | C9: 1675 | D9: 1802 | E9: 2168 | F9: 2613 | G9: S1/S2/S3
A10: Total Revenue | B10: 2703 | C10: 2679 | D10: 3233 | E10: 4007 | F10: 4920 | G10: S1/S2/S3
A11: YoY Revenue Growth | B11: - | C11: =C10/B10-1 -> -0.0088790233 | D11: =D10/C10-1 -> 0.20679358 | E11: =E10/D10-1 -> 0.23940612 | F11: =F10/E10-1 -> 0.22785126 | G11: Calculated
A12: Cost of Sales | B12: -131 | C12: -106 | D12: -154 | E12: -121 | F12: -121 | G12: S1/S2/S3
A13: Gross Profit | B13: 2572 | C13: 2573 | D13: 3079 | E13: 3886 | F13: 4799 | G13: S1/S2/S3
A14: Gross Margin | B14: =B13/B10 -> 0.95153533 | C14: =C13/C10 -> 0.960433 | D14: =D13/D10 -> 0.95236622 | E14: =E13/E10 -> 0.96980285 | F14: =F13/F10 -> 0.9754065 | G14: Calculated
A15: Research & Development | B15: -995 | C15: -1133 | D15: -1979 | E15: -2071 | F15: -2776 | G15: S1/S2/S3
A16: R&D as % of Revenue | B16: =-B15/B10 -> 0.36810951 | C16: =-C15/C10 -> 0.422919 | D16: =-D15/D10 -> 0.61212496 | E16: =-E15/E10 -> 0.51684552 | F16: =-F15/F10 -> 0.56422764 | G16: Calculated
A17: Selling, General & Administrative | B17: -897 | C17: -762 | D17: -983 | E17: -984 | F17: -1115 | G17: S1/S2/S3
A18: SG&A as % of Revenue | B18: =-B17/B10 -> 0.3318535 | C18: =-C17/C10 -> 0.28443449 | D18: =-D17/D10 -> 0.30405196 | E18: =-E17/E10 -> 0.24557025 | F18: =-F17/F10 -> 0.22662602 | G18: Calculated
A19: Other Operating Expense | B19: -47 | C19: -7 | D19: -6 | E19: 0 | F19: -8 | G19: S1/S2/S3
A20: Operating Income | B20: 633 | C20: 671 | D20: 111 | E20: 831 | F20: 900 | G20: S1/S2/S3
A21: Operating Margin | B21: =B20/B10 -> 0.23418424 | C21: =C20/C10 -> 0.25046659 | D21: =D20/D10 -> 0.034333436 | E21: =E20/E10 -> 0.20738707 | F21: =F20/F10 -> 0.18292683 | G21: Calculated
A22: Pre-Tax Income | B22: 786 | C22: 671 | D22: 212 | E22: 720 | F22: 1157 | G22: S1/S2/S3
A23: Net Income | B23: 549 | C23: 524 | D23: 306 | E23: 792 | F23: 904 | G23: S1/S2/S3
A24: Net Margin | B24: =B23/B10 -> 0.20310766 | C24: =C23/C10 -> 0.19559537 | D24: =D23/D10 -> 0.094648933 | E24: =E23/E10 -> 0.19765411 | F24: =F23/F10 -> 0.18373984 | G24: Calculated
A25: Diluted EPS | B25: 0.54 | C25: 0.51 | D25: 0.29 | E25: 0.75 | F25: 0.85 | G25: S1/S2/S3
A26: Diluted Weighted Avg. Shares (mm) | B26: 1025 | C26: 1028 | D26: 1044 | E26: 1063 | F26: 1068 | G26: S1/S2/S3
A29: Cash Flow
A30: Cash From Operations | B30: 458 | C30: 739 | D30: 1090 | E30: 397 | F30: 1524 | G30: S1/S2/S3
A31: Capital Expenditures — PP&E | B31: -34 | C31: -64 | D31: -92 | E31: -219 | F31: -545 | G31: S1/S2/S3
A32: Simple Free Cash Flow (CFO - Capex) | B32: =B30+B31 -> 424 | C32: =C30+C31 -> 675 | D32: =D30+D31 -> 998 | E32: =E30+E31 -> 178 | F32: =F30+F31 -> 979 | G32: Calculated
A33: Cash & Cash Equivalents, End of Period | B33: 1004 | C33: 1554 | D33: 1923 | E33: 2085 | F33: 2751 | G33: S1/S2/S3

Sheet Revenue Mix & KPIs
A1: Arm Revenue Mix & Historical KPI Trends
A3: $ in millions | Fiscal year ended March 31
H4: Series | I4: FY2022A | J4: FY2023A | K4: FY2024A | L4: FY2025A | M4: FY2026A
B5: FY2022A | C5: FY2023A | D5: FY2024A | E5: FY2025A | F5: FY2026A | H5: License & Other | I5: 1141 | J5: 1004 | K5: 1431 | L5: 1839 | M5: 2307
H6: Royalty | I6: 1562 | J6: 1675 | K6: 1802 | L6: 2168 | M6: 2613
A7: Revenue Mix
A8: License & Other Revenue | B8: 1141 | C8: 1004 | D8: 1431 | E8: 1839 | F8: 2307
A9: License & Other % of Revenue | B9: =B8/B12 -> 0.42212357 | C9: =C8/C12 -> 0.3747667 | D9: =D8/D12 -> 0.44262295 | E9: =E8/E12 -> 0.45894684 | F9: =F8/F12 -> 0.46890244
A10: Royalty Revenue | B10: 1562 | C10: 1675 | D10: 1802 | E10: 2168 | F10: 2613
A11: Royalty % of Revenue | B11: =B10/B12 -> 0.57787643 | C11: =C10/C12 -> 0.6252333 | D11: =D10/D12 -> 0.55737705 | E11: =E10/E12 -> 0.54105316 | F11: =F10/F12 -> 0.53109756
A12: Total Revenue | B12: 2703 | C12: 2679 | D12: 3233 | E12: 4007 | F12: 4920
A13: Royalty / License Revenue Ratio | B13: =B10/B8 -> 1.3689746 | C13: =C10/C8 -> 1.6683267 | D13: =D10/D8 -> 1.2592593 | E13: =E10/E8 -> 1.1789016 | F13: =F10/F8 -> 1.1326398
A16: Key Profitability & Cash Metrics
A17: Gross Margin | B17: ='Historical Financials'!B14 -> 0.95153533 | C17: ='Historical Financials'!C14 -> 0.960433 | D17: ='Historical Financials'!D14 -> 0.95236622 | E17: ='Historical Financials'!E14 -> 0.96980285 | F17: ='Historical Financials'!F14 -> 0.9754065
A18: Operating Margin | B18: ='Historical Financials'!B21 -> 0.23418424 | C18: ='Historical Financials'!C21 -> 0.25046659 | D18: ='Historical Financials'!D21 -> 0.034333436 | E18: ='Historical Financials'!E21 -> 0.20738707 | F18: ='Historical Financials'!F21 -> 0.18292683
A19: Net Margin | B19: ='Historical Financials'!B24 -> 0.20310766 | C19: ='Historical Financials'!C24 -> 0.19559537 | D19: ='Historical Financials'!D24 -> 0.094648933 | E19: ='Historical Financials'!E24 -> 0.19765411 | F19: ='Historical Financials'!F24 -> 0.18373984
A20: R&D as % of Revenue | B20: ='Historical Financials'!B16 -> 0.36810951 | C20: ='Historical Financials'!C16 -> 0.422919 | D20: ='Historical Financials'!D16 -> 0.61212496 | E20: ='Historical Financials'!E16 -> 0.51684552 | F20: ='Historical Financials'!F16 -> 0.56422764
A21: Simple FCF Margin | B21: ='Historical Financials'!B32/'Historical Financials'!B10 -> 0.15686275 | C21: ='Historical Financials'!C32/'Historical Financials'!C10 -> 0.25195969 | D21: ='Historical Financials'!D32/'Historical Financials'!D10 -> 0.30869162 | E21: ='Historical Financials'!E32/'Historical Financials'!E10 -> 0.044422261 | F21: ='Historical Financials'!F32/'Historical Financials'!F10 -> 0.19898374
A22: Diluted EPS | B22: 0.54 | C22: 0.51 | D22: 0.29 | E22: 0.75 | F22: 0.85

Sheet Balance Sheet Snapshot
A1: Arm Holdings plc — Balance Sheet Snapshot
A3: $ in millions | Period-end values
B5: FY2023A | C5: FY2024A | D5: FY2025A | E5: FY2026A
A7: Selected Balance Sheet Items
A8: Cash & Cash Equivalents | B8: 1554 | C8: 1923 | D8: 2085 | E8: 2751
A9: Short-Term Investments | B9: 661 | C9: 1000 | D9: 740 | E9: 850
A10: Accounts Receivable | B10: 999 | C10: 781 | D10: 1107 | E10: 1300
A11: Contract Assets — Current | B11: 154 | C11: 336 | D11: 642 | E11: 977
A12: Total Current Assets | B12: 3537 | C12: 4197 | D12: 4830 | E12: 6236
A13: Property & Equipment, Net | B13: 185 | C13: 215 | D13: 394 | E13: 772
A14: Total Assets | B14: 6866 | C14: 7927 | D14: 8932 | E14: 10703
A15: Total Current Liabilities | B15: 1363 | C15: 1505 | D15: 929 | E15: 1040
A16: Total Liabilities | B16: 2815 | C16: 2632 | D16: 2093 | E16: 2417
A17: Shareholders' Equity | B17: 4051 | C17: 5295 | D17: 6839 | E17: 8286
A18: Net Cash + Short-Term Investments | B18: =B8+B9 -> 2215 | C18: =C8+C9 -> 2923 | D18: =D8+D9 -> 2825 | E18: =E8+E9 -> 3601
A19: Current Ratio | B19: =B12/B15 -> 2.595011 | C19: =C12/C15 -> 2.7887043 | D19: =D12/D15 -> 5.1991389 | E19: =E12/E15 -> 5.9961538

Sheet Source Log
A1: Primary Source Log
A4: Source ID | B4: Document | C4: Periods Used | D4: Primary URL | E4: Used For
A5: S1 | B5: Arm Holdings plc Form 20-F, FY2026 | C5: FY2024–FY2026 | D5: https://www.sec.gov/Archives/edgar/data/1973239/000197323926000097/arm-20260331.htm | E5: FY2026/FY2025 income statement, revenue mix, cash flow, balance sheet
A6: S2 | B6: Arm Holdings plc Form 20-F, FY2025 | C6: FY2023–FY2025 | D6: https://www.sec.gov/Archives/edgar/data/1973239/000197323925000016/arm-20250331.htm | E6: FY2025/FY2024/FY2023 income statement; FY2025/FY2024 balance sheet and cash flow
A7: S3 | B7: Arm Holdings plc Form 20-F, FY2024 | C7: FY2022–FY2024 | D7: https://www.sec.gov/Archives/edgar/data/1973239/000197323924000012/arm-20240331.htm | E7: FY2022–FY2024 income statement; FY2022–FY2024 cash flow; FY2023/FY2024 balance sheet
A8: S4 | B8: Arm Holdings plc FY2024 Results / SEC filing | C8: FY2023–FY2024 | D8: https://investors.arm.com/node/7151/html | E8: Cross-check for revenue, operating income, operating cash flow, and selected KPIs
A9: S5 | B9: Arm Holdings plc Final IPO Prospectus (424B4) | C9: IPO pricing, Sept. 2023 | D9: https://www.sec.gov/Archives/edgar/data/1973239/000119312523235320/d550931d424b4.htm | E9: IPO price, shares outstanding, offering structure, IPO-date valuation inputs
A10: S6 | B10: Arm Holdings plc Final Prospectus — offering shares section | C10: Sept. 2023 | D10: https://www.sec.gov/Archives/edgar/data/1973239/000119312523235320/d550931d424b4.htm | E10: 1,026.055mm post-offering shares and 95.5mm base ADSs offered
A11: S7 | B11: Wall Street Journal market table dated Sept. 14, 2023 | C11: 9/13/2023 closes | D11: https://www.wsj.com/public/resources/documents/EhFzNsf5wgGAZqtIg8e7-WSJNewsPaper-9-14-2023.pdf | E11: Exact 9/13/2023 closing prices for all six CCA peers
A12: S8 | B12: Synopsys FY2023 Q3 Form 10-Q | C12: 7/31/2023 | D12: https://www.sec.gov/Archives/edgar/data/883241/000088324123000016/snps-20230731.htm | E12: SNPS shares outstanding, cash/ST investments, debt
A13: S9 | B13: Cadence FY2023 Q2 Form 10-Q | C13: 6/30/2023 | D13: https://www.sec.gov/Archives/edgar/data/813672/000081367223000041/cdns-20230630.htm | E13: CDNS shares outstanding, cash, debt
A14: S10 | B14: NVIDIA FY2024 Q2 Form 10-Q | C14: 7/30/2023 | D14: https://www.sec.gov/Archives/edgar/data/1045810/000104581023000175/nvda-20230730.htm | E14: NVDA shares outstanding, cash/marketable securities, debt
A15: S11 | B15: AMD FY2023 Q2 Form 10-Q | C15: 7/1/2023 | D15: https://www.sec.gov/Archives/edgar/data/2488/000000248823000139/amd-20230701.htm | E15: AMD shares outstanding, cash/ST investments, debt
... A25: S21 | B25: Arm Investor Relations profile | C25: 2026 | D25: https://investors.arm.com/ | E25: 350B+ Arm-based chips shipped; 99% smartphone penetration; company positioning

Sheet IPO Snapshot
A1: Arm Holdings plc — IPO-Date Financial Snapshot
A3: Valuation date: September 13, 2023 | $ in millions except per-share data
A5: IPO Transaction
A6: Metric | B6: Value | C6: Source / Note
A7: IPO Price per ADS | B7: 51 | C7: Arm final prospectus
A8: Ordinary Shares Outstanding Post-Offering (mm) | B8: 1026.0549 | C8: Arm final prospectus
A9: Base ADSs Offered (mm) | B9: 95.5 | C9: Arm final prospectus
A10: ADSs Sold incl. Greenshoe (mm) | B10: 102.5 | C10: Arm final prospectus / full exercise
A11: Implied Basic Equity Value | B11: =B7*B8 -> 52328.798 | C11: Calculated
A12: Cash & Cash Equivalents — FY2023A | B12: 1554 | C12: FY2023 audited financials
A13: Short-Term Investments — FY2023A | B13: 661 | C13: FY2023 audited financials
A14: Financial Debt Used in EV | B14: 0 | C14: No material funded debt identified; operating leases excluded
A16: Valuation Metric | B16: Value | C16: Source / Formula
A17: FY2023A Revenue | B17: 2679 | C17: Audited FY2023
A18: FY2023A Operating Income | B18: 671 | C18: Audited FY2023
A19: FY2023A Net Income | B19: 524 | C19: Audited FY2023
A20: Net Cash + Short-Term Investments | B20: =B12+B13-B14 -> 2215 | C20: Cash + short-term investments - debt
A21: Implied Enterprise Value | B21: =B11-B20 -> 50113.798 | C21: Equity value - net cash
A22: IPO EV / Revenue | B22: =B21/B17 -> 18.706158 | C22: Calculated
A23: IPO P / E | B23: =B11/B19 -> 99.864118 | C23: Calculated
A26: Why this snapshot matters: the IPO valuation must use information available at the time of pricing. FY2024–FY2026 results are useful for retrospective analysis later, but they should not be used to judge whether the September 2023 IPO price was fair.

Sheet CCA
A1: Arm Holdings plc — Comparable Company Analysis (Step 3)
A3: Valuation date: September 13, 2023 | Market data to be measured as close to IPO pricing as practical
A5: Peer Universe
A6: Company | B6: Ticker | C6: Peer Type | D6: Why Included
A7: Synopsys | B7: SNPS | C7: Core / IP & EDA | D7: High-margin semiconductor IP/design software economics; recurring, asset-light model
A8: Cadence Design Systems | B8: CDNS | C8: Core / IP & EDA | D8: High-margin EDA and semiconductor IP; closest public business-model analogue
A9: NVIDIA | B9: NVDA | C9: Growth semiconductor | D9: Premium design-led semiconductor business; relevant AI/data-center growth benchmark
A10: AMD | B10: AMD | C10: Semiconductor design | D10: Fabless CPU/GPU designer; direct architecture competition in compute
A11: Qualcomm | B11: QCOM | C11: Semiconductor + licensing | D11: Fabless chips plus valuable IP/licensing economics; useful royalty-model comparison
A12: Broadcom | B12: AVGO | C12: Diversified semiconductor | D12: High-margin semiconductor/design exposure and strong cash generation
A15: Trading Comparables — Framework
A16: Company | B16: Ticker | C16: Share Price | D16: Diluted Shares (mm) | E16: Equity Value ($mm) | F16: Debt ($mm) | G16: Cash & ST Investments ($mm) | H16: Enterprise Value ($mm) | I16: LTM Revenue ($mm) | J16: LTM EBITDA ($mm) | K16: LTM Net Income ($mm) | L16: EV / Revenue | M16: EV / EBITDA | N16: P / E | O16: Market Price Source | P16: Shares / Balance Sheet Source | Q16: LTM Financial Source | R16: Valid P/E Helper
A17: Synopsys | B17: SNPS | C17: 466.86 | D17: 152.08382 | E17: =C17*D17 -> 71001.851 | F17: 18.165 | G17: 1834.587 | H17: =E17+F17-G17 -> 69185.429 | I17: 4800 | J17: 1370 | K17: 1040 | L17: =H17/I17 -> 14.413631 | M17: =H17/J17 -> 50.500313 | N17: =IF(K17<=0,"N.M.",E17/K17) -> 68.27101 | O17: https://www.wsj.com/public/resources/documents/EhFzNsf5wgGAZqtIg8e7-WSJNewsPaper-9-14-2023.pdf | P17: https://www.sec.gov/Archives/edgar/data/883241/000088324123000016/snps-20230731.htm | Q17: https://www.macrotrends.net/stocks/charts/SNPS/synopsys/ebitda-margin | R17: =N17 -> 68.27101
A18: Cadence Design Systems | B18: CDNS | C18: 241.13 | D18: 271.79 | E18: =C18*D18 -> 65536.723 | F18: 648.551 | G18: 873.925 | H18: =E18+F18-G18 -> 65311.349 | I18: 3800 | J18: 1230 | K18: 890 | L18: =H18/I18 -> 17.187197 | M18: =H18/J18 -> 53.098657 | N18: =IF(K18<=0,"N.M.",E18/K18) -> 73.636767 | O18: https://www.wsj.com/public/resources/documents/EhFzNsf5wgGAZqtIg8e7-WSJNewsPaper-9-14-2023.pdf | P18: https://www.sec.gov/Archives/edgar/data/813672/000081367223000041/cdns-20230630.htm | Q18: https://www.macrotrends.net/stocks/charts/CDNS/cadence-design-systems/ebitda-margin | R18: =N18 -> 73.636767
A19: NVIDIA | B19: NVDA | C19: 454.85 | D19: 2470 | E19: =C19*D19 -> 1123479.5 | F19: 9705 | G19: 16020 | H19: =E19+F19-G19 -> 1117164.5 | I19: 32680 | J19: 12380 | K19: 10330 | L19: =H19/I19 -> 34.18496 | M19: =H19/J19 -> 90.239459 | N19: =IF(K19<=0,"N.M.",E19/K19) -> 108.75891 | O19: https://www.wsj.com/public/resources/documents/EhFzNsf5wgGAZqtIg8e7-WSJNewsPaper-9-14-2023.pdf | P19: https://www.sec.gov/Archives/edgar/data/1045810/000104581023000175/nvda-20230730.htm | Q19: https://www.macrotrends.net/stocks/charts/NVDA/nvidia/ebitda-margin | R19: =N19 -> 108.75891
A20: AMD | B20: AMD | C20: 107.71 | D20: 1615.6714 | E20: =C20*D20 -> 174023.96 | F20: 2500 | G20: 6300 | H20: =E20+F20-G20 -> 170223.96 | I20: 21880 | J20: 3940 | K20: -30 | L20: =H20/I20 -> 7.7798887 | M20: =H20/J20 -> 43.204052 | N20: =IF(K20<=0,"N.M.",E20/K20) -> N.M. | O20: https://www.wsj.com/public/resources/documents/EhFzNsf5wgGAZqtIg8e7-WSJNewsPaper-9-14-2023.pdf | P20: https://www.sec.gov/Archives/edgar/data/2488/000000248823000139/amd-20230701.htm | Q20: https://www.macrotrends.net/stocks/charts/AMD/amd/ebitda-margin | R20: =N21 -> 14.570023
A21: Qualcomm | B21: QCOM | C21: 112.64 | D21: 1115 | E21: =C21*D21 -> 125593.6 | F21: 15444 | G21: 8631 | H21: =E21+F21-G21 -> 132406.6 | I21: 38580 | J21: 11880 | K21: 8620 | L21: =H21/I21 -> 3.432001 | M21: =H21/J21 -> 11.145337 | N21: =IF(K21<=0,"N.M.",E21/K21) -> 14.570023 | O21: https://www.wsj.com/public/resources/documents/EhFzNsf5wgGAZqtIg8e7-WSJNewsPaper-9-14-2023.pdf | P21: https://www.sec.gov/Archives/edgar/data/804328/000080432823000043/qcom-20230625.htm | Q21: https://www.macrotrends.net/stocks/charts/QCOM/qualcomm/ebitda-margin | R21: =N22 -> 25.381002
A22: Broadcom | B22: AVGO | C22: 852.93 | D22: 412.7355 | E22: =C22*D22 -> 352034.49 | F22: 40958 | G22: 12055 | H22: =E22+F22-G22 -> 380937.49 | I22: 35450 | J22: 20070 | K22: 13870 | L22: =H22/I22 -> 10.745769 | M22: =H22/J22 -> 18.980443 | N22: =IF(K22<=0,"N.M.",E22/K22) -> 25.381002 | O22: https://www.wsj.com/public/resources/documents/EhFzNsf5wgGAZqtIg8e7-WSJNewsPaper-9-14-2023.pdf | P22: https://www.sec.gov/Archives/edgar/data/1730168/000173016823000077/avgo-20230730.htm | Q22: https://www.macrotrends.net/stocks/charts/AVGO/broadcom/ebitda-margin
A24: Statistic
A25: Median | L25: =MEDIAN(L17:L22) -> 12.5797 | M25: =MEDIAN(M17:M22) -> 46.852182 | N25: =MEDIAN(R17:R21) -> 68.27101
A26: 25th Percentile | L26: =quartile.inc(L17:L22,1) -> #NAME? | M26: =quartile.inc(M17:M22,1) -> #NAME? | N26: =quartile.inc(R17:R21,1) -> #NAME?
A27: 75th Percentile | L27: =quartile.inc(L17:L22,3) -> #NAME? | M27: =quartile.inc(M17:M22,3) -> #NAME? | N27: =quartile.inc(R17:R21,3) -> #NAME?
A29: Peer-multiple statistics will populate after the six peer rows are researched and entered.
A30: Arm IPO Reference Valuation
A31: Metric | B31: Arm IPO | C31: Link | F31: Use only financial information that was publicly available by September 13, 2023. Market prices should be from the IPO pricing date (or nearest trading date). For each peer, use the latest reported balance sheet and LTM financials available at that date. Later results must not leak into the IPO-date valuation.
A32: Equity Value ($mm) | B32: ='IPO Snapshot'!B11 -> 52328.798 | C32: IPO Snapshot
A33: Enterprise Value ($mm) | B33: ='IPO Snapshot'!B21 -> 50113.798 | C33: IPO Snapshot
A34: EV / Revenue | B34: ='IPO Snapshot'!B22 -> 18.706158 | C34: IPO Snapshot
A35: P / E | B35: ='IPO Snapshot'!B23 -> 99.864118 | C35: IPO Snapshot
A38: Initial CCA Read-Through
A39: Metric | B39: Arm IPO | C39: Peer Median | D39: Arm Premium / (Discount)
A40: EV / Revenue | B40: ='IPO Snapshot'!B22 -> 18.706158 | C40: =L25 -> 12.5797 | D40: =B40/C40-1 -> 0.4870115
A41: EV / EBITDA | B41: N/A | C41: =M25 -> 46.852182 | D41: N/A
A42: P / E | B42: ='IPO Snapshot'!B23 -> 99.864118 | C42: =N25 -> 68.27101 | D42: =B42/C42-1 -> 0.46276021
A43: Core IP/EDA EV / Revenue Median | B43: =AVERAGE(L17:L18) -> 15.800414 | C43: =AVERAGE(L17:L18) -> 15.800414
A44: Comment | B44: Arm priced above the full peer median on EV/Revenue, but below the very high-growth NVIDIA multiple.

Sheet IPO Valuation
A1: Arm Holdings plc — IPO Implied Valuation Range
A3: Valuation date: September 13, 2023 | $ in millions except per-share data
A5: Valuation Inputs | J5: Method | K5: Implied Share Price
A6: Metric | B6: Value | C6: Source | J6: Peer Median | K6: 35
A7: FY2023 Revenue | B7: ='IPO Snapshot'!B17 -> 2679 | C7: IPO Snapshot | J7: Core IP/EDA | K7: 43.41
A8: Net Cash + ST Investments | B8: ='IPO Snapshot'!B20 -> 2215 | C8: IPO Snapshot | J8: 75th Percentile | K8: 45.22
A9: Post-Offering Shares (mm) | B9: ='IPO Snapshot'!B8 -> 1026.0549 | C9: IPO Snapshot | J9: IPO Price | K9: 51
A10: IPO Price | B10: ='IPO Snapshot'!B7 -> 51 | C10: IPO Snapshot
A11: IPO Enterprise Value | B11: ='IPO Snapshot'!B21 -> 50113.798 | C11: IPO Snapshot
A14: Comparable Company Implied Valuation
A15: Method | B15: EV / Revenue | C15: Implied EV | D15: Implied Equity Value | E15: Implied Share Price | F15: Discount to IPO | G15: Interpretation | H15: Source
A16: Full Peer Median | B16: =CCA!L25 -> 12.5797 | C16: =B16*$B$7 -> 33701.016 | D16: =C16+$B$8 -> 35916.016 | E16: =D16/$B$9 -> 35.003992 | F16: =E16/$B$10-1 -> -0.31364722 | G16: Broad cross-sector anchor; includes mature and premium semiconductor names. | H16: CCA
A17: Core IP / EDA Average | B17: =AVERAGE(CCA!L17:L18) -> 15.800414 | C17: =B17*$B$7 -> 42329.309 | D17: =C17+$B$8 -> 44544.309 | E17: =D17/$B$9 -> 43.413185 | F17: =E17/$B$10-1 -> -0.14876108 | G17: Closest business-model analogues: Synopsys and Cadence. | H17: CCA
A18: Peer 75th Percentile | B18: =CCA!L27 -> #NAME? | C18: =B18*$B$7 -> #NAME? | D18: =C18+$B$8 -> #NAME? | E18: =D18/$B$9 -> #NAME? | F18: =E18/$B$10-1 -> #NAME? | G18: Premium case reflecting Arm's royalty model, ecosystem scale, and growth option value. | H18: CCA
A19: Actual IPO | B19: ='IPO Snapshot'!B22 -> 18.706158 | C19: =B19*$B$7 -> 50113.798 | D19: =C19+$B$8 -> 52328.798 | E19: =D19/$B$9 -> 51 | F19: =E19/$B$10-1 -> 0 | G19: SoftBank priced at the top of the marketed range. | H19: IPO Snapshot
A22: Valuation Conclusion
A23: At $51 per ADS, Arm priced above every central comp-based reference point in this analysis. The full-peer median implies roughly $35 per share, the core IP/EDA reference implies roughly $43, and the peer 75th percentile implies roughly $45. The IPO therefore required an approximately 13–15% premium to the closest high-quality public business-model references. That premium was aggressive, but not irrational: Arm had unusually high gross margins, a recurring royalty stream, dominant mobile architecture share, and credible growth optionality in cloud, automotive, Armv9, and AI. The appropriate conclusion is 'premium-priced' rather than simply 'overvalued.'

Sheet DCF Valuation
A1: Arm Holdings — Discounted Cash Flow Valuation
A2: Forward-looking cross-check: is Arm fairly valued TODAY, independent of the IPO or the historical re-rating
A4: 1. Cost of Capital (WACC)
A5: Input | B5: Value | C5: Source / Note
A6: Risk-Free Rate (10Y UST) | B6: 0.0474 | C6: 10-year Treasury yield, end of July 2026 (CNBC/Damodaran)
A7: Equity Risk Premium | B7: 0.0423 | C7: Implied ERP, start of August 2026 (Damodaran, NYU Stern)
A8: Assumed Beta (peer-based estimate) | B8: 1.2 | C8: Estimate, not Arm's own observed beta — see limitation note below
A9: Cost of Equity (CAPM) | B9: =B6+B8*B7 -> 0.09816 | C9: Rf + Beta × ERP
A10: Cost of Debt / Weight of Debt | B10: n/a | C10: No material funded debt (consistent with IPO Snapshot and Post-IPO Performance tabs)
A11: WACC | B11: =B9 -> 0.09816 | C11: Cost of Equity, since debt is immaterial to Arm's capital structure
A13: 2. Explicit Forecast: Revenue &amp; Unlevered FCF (FY2027E–FY2031E)
A14: Metric | B14: FY2026A | C14: FY2027E | D14: FY2028E | E14: FY2029E | F14: FY2030E | G14: FY2031E
A15: License &amp; Other Revenue | B15: 2307 | C15: =B15*(1+0.25) -> 2883.75 | D15: =C15*(1+0.21) -> 3489.3375 | E15: =D15*(1+0.17) -> 4082.5249 | F15: =E15*(1+0.13) -> 4613.2531 | G15: =F15*(1+0.1) -> 5074.5784
A16: Royalty Revenue | B16: 2613 | C16: =B16*(1+0.2) -> 3135.6 | D16: =C16*(1+0.18) -> 3700.008 | E16: =D16*(1+0.16) -> 4292.0093 | F16: =E16*(1+0.14) -> 4892.8906 | G16: =F16*(1+0.12) -> 5480.0374
A17: Total Revenue | B17: =B15+B16 -> 4920 | C17: =C15+C16 -> 6019.35 | D17: =D15+D16 -> 7189.3455 | E17: =E15+E16 -> 8374.5342 | F17: =F15+F16 -> 9506.1437 | G17: =G15+G16 -> 10554.616
A19: Non-GAAP Operating Margin (assumed) | B19: 0.43 | C19: 0.44 | D19: 0.45 | E19: 0.458 | F19: 0.465 | G19: 0.47 | H19: Improves as R&D/SBC normalize post-IPO; FY26A actual was 43.0%
A20: Unlevered Operating Income | B20: =B17*B19 -> 2115.6 | C20: =C17*C19 -> 2648.514 | D20: =D17*D19 -> 3235.2055 | E20: =E17*E19 -> 3835.5366 | F20: =F17*F19 -> 4420.3568 | G20: =G17*G19 -> 4960.6695
A21: Less: Cash Taxes (assumed rate) | B21: 0.18 | H21: Simplified assumption — blended effective rate, not a full jurisdictional build
A22: NOPAT | B22: =B20*(1-$B$21) -> 1734.792 | C22: =C20*(1-$B$21) -> 2171.7815 | D22: =D20*(1-$B$21) -> 2652.8685 | E22: =E20*(1-$B$21) -> 3145.14 | F22: =F20*(1-$B$21) -> 3624.6926 | G22: =G20*(1-$B$21) -> 4067.749
A23: Plus: D&amp;A (% of revenue, assumed) | B23: =B17*0.02 -> 98.4 | C23: =C17*0.02 -> 120.387 | D23: =D17*0.02 -> 143.78691 | E23: =E17*0.02 -> 167.49068 | F23: =F17*0.02 -> 190.12287 | G23: =G17*0.02 -> 211.09232 | H23: Assumed 2.0% of revenue — asset-light model
A24: Less: CapEx (% of revenue, assumed) | B24: =-B17*0.025 -> -123 | C24: =-C17*0.025 -> -150.48375 | D24: =-D17*0.025 -> -179.73364 | E24: =-E17*0.025 -> -209.36335 | F24: =-F17*0.025 -> -237.65359 | G24: =-G17*0.025 -> -263.8654 | H24: Assumed 2.5% of revenue
A25: Less: Increase in NWC (% of revenue, assumed) | B25: =-B17*0.01 -> -49.2 | C25: =-C17*0.01 -> -60.1935 | D25: =-D17*0.01 -> -71.893455 | E25: =-E17*0.01 -> -83.745342 | F25: =-F17*0.01 -> -95.061437 | G25: =-G17*0.01 -> -105.54616 | H25: Assumed 1.0% of revenue
A26: Unlevered Free Cash Flow | B26: =B22+B23+B24+B25 -> 1660.992 | C26: =C22+C23+C24+C25 -> 2081.4912 | D26: =D22+D23+D24+D25 -> 2545.0283 | E26: =E22+E23+E24+E25 -> 3019.522 | F26: =F22+F23+F24+F25 -> 3482.1004 | G26: =G22+G23+G24+G25 -> 3909.4297
A28: 3. Discounting &amp; Terminal Value
A29: Metric | B29: FY2027E | C29: FY2028E | D29: FY2029E | E29: FY2030E | F29: FY2031E
A30: Discount Period | B30: 1 | C30: 2 | D30: 3 | E30: 4 | F30: 5
A31: Discount Factor | B31: =1/(1+$B$11)^B30 -> 0.91061412 | C31: =1/(1+$B$11)^C30 -> 0.82921807 | D31: =1/(1+$B$11)^D30 -> 0.75509768 | E31: =1/(1+$B$11)^E30 -> 0.68760261 | F31: =1/(1+$B$11)^F30 -> 0.62614065
A32: Unlevered FCF | B32: =C26 -> 2081.4912 | C32: =D26 -> 2545.0283 | D32: =E26 -> 3019.522 | E32: =F26 -> 3482.1004 | F32: =G26 -> 3909.4297
A33: PV of FCF | B33: =B32*B31 -> 1895.4353 | C33: =C32*C31 -> 2110.3835 | D33: =D32*D31 -> 2280.0341 | E33: =E32*E31 -> 2394.3014 | F33: =F32*F31 -> 2447.8528
A35: Terminal Growth Rate | B35: 0.035 | C35: Roughly nominal long-run GDP growth — deliberately conservative given AI/data-center uncertainty
A36: Terminal Value (Perpetuity Growth, undiscounted) | B36: =G26*(1+B35)/($B$11-B35) -> 64063.644 | C36: FY2031E FCF x (1+g) / (WACC - g)
A37: PV of Terminal Value | B37: =B36*F31 -> 40112.851
A38: Cross-Check: Exit-Multiple Implied TV (EV/Revenue) | B38: 20 | C38: =B38*F17 -> 190122.87 | D38: Assumed exit multiple (moderated from today's 58x) × FY2031E revenue — sanity check on perpetuity-growth TV
A41: 4. Implied Valuation
A42: Metric | B42: Value
A43: Sum of PV of Explicit FCFs | B43: =SUM(B33:F33) -> 11128.007
A44: Implied Enterprise Value | B44: =B43+B37 -> 51240.858
A45: Plus: Net Cash + ST Investments (current) | B45: ='Post-IPO Performance'!C49 -> 3601
A46: Implied Equity Value | B46: =B44+B45 -> 54841.858
A47: Diluted Shares Outstanding (current, mm) | B47: ='Post-IPO Performance'!C47 -> 1064.0553
...

Sheet Post-IPO Performance
A1: Arm Holdings — Post-IPO Operating & Market Performance
A3: Retrospective analysis using information reported after the September 2023 IPO
A5: Operating Performance Since IPO | J5: Series | K5: FY2023A | L5: FY2024A | M5: FY2025A | N5: FY2026A
A6: Metric | B6: FY2023A | C6: FY2024A | D6: FY2025A | E6: FY2026A | F6: FY23–FY26 CAGR | J6: Total Revenue | K6: 2679 | L6: 3233 | M6: 4007 | N6: 4920
A7: Revenue | B7: 2679 | C7: 3233 | D7: 4007 | E7: 4920 | F7: =(E7/B7)^(1/3)-1 -> 0.22460905 | J7: License & Other | K7: 1004 | L7: 1431 | M7: 1839 | N7: 2307
A8: License & Other Revenue | B8: 1004 | C8: 1431 | D8: 1839 | E8: 2307 | F8: =(E8/B8)^(1/3)-1 -> 0.31958679 | J8: Royalty Revenue | K8: 1675 | L8: 1802 | M8: 2168 | N8: 2613
A9: Royalty Revenue | B9: 1675 | C9: 1802 | D9: 2168 | E9: 2613 | F9: =(E9/B9)^(1/3)-1 -> 0.159778
A10: Operating Income | B10: 671 | C10: 111 | D10: 831 | E10: 900 | F10: =(E10/B10)^(1/3)-1 -> 0.10282515
A11: Net Income | B11: 524 | C11: 306 | D11: 792 | E11: 904 | F11: =(E11/B11)^(1/3)-1 -> 0.19934938
A12: Diluted EPS | B12: 0.51 | C12: 0.29 | D12: 0.75 | E12: 0.85 | F12: =(E12/B12)^(1/3)-1 -> 0.1856311
A13: Cash & Cash Equivalents | B13: 1554 | C13: 1923 | D13: 2085 | E13: 2751 | F13: =(E13/B13)^(1/3)-1 -> 0.20970607
A17: Market Milestones
A18: Date | B18: Milestone | C18: Price / Metric | D18: Return vs $51 IPO | E18: Interpretation | F18: Source
A19: Sep. 14, 2023 | B19: First-day close | C19: 63.59 | D19: =C19/51-1 -> 0.24686275 | E19: Strong initial demand; nearly 25% first-day gain. | F19: Reuters
A20: Mar. 12, 2024 | B20: IPO lock-up expiry | C20: 129.5 | D20: =C20/51-1 -> 1.5392157 | E20: Stock more than doubled; only 9.5% public float before lock-up expiry. | F20: Reuters
A21: Jan. 24, 2025 | B21: Reuters IPO review | E21: Reuters reported Arm shares had more than doubled since IPO. | F21: Reuters
A22: Jul. 27, 2026 | B22: Recent pre-Q1 FY27 close | C22: 266.43 | D22: =C22/51-1 -> 4.2241176 | E22: Reference point before Q1 FY27 results. | F22: ChartExchange
A23: Jul. 29, 2026 | B23: Q1 FY27 results | E23: Revenue beat expectations; shares fell ~7% after hours amid smartphone royalty caution. | F23: Reuters
A26: Q1 FY2027 Check-In
A27: Metric | B27: Q1 FY2027 | C27: YoY | D27: Read-Through
A28: Revenue | B28: 1290 | D28: Above Street expectations; AI/data-center demand remained strong.
A29: Royalty Revenue | B29: 715 | C29: 0.22 | D29: Growth supported by more complex chips and data-center adoption.
A30: License Revenue | B30: 574 | C30: 0.23 | D30: Continued healthy licensing demand.
A31: Q2 Revenue Guidance | B31: 1380 | D31: Above analyst consensus cited by Reuters.
A34: Retrospective Verdict
A35: Arm's total return from IPO to August 2026 was 5.34x — but that return decomposes cleanly into two distinct sources. EPS grew 1.67x (from $0.51 to $0.85 GAAP diluted), reflecting genuine, substantial operating improvement. Separately, the P/E multiple expanded 3.20x (from 100x to 320x), and EV/Revenue expanded a consistent 3.11x (18.7x to 58.1x) — two independent multiples pointing to the same conclusion. These two factors multiply exactly to the total return (1.67 x 3.20 = 5.34), meaning multiple re-rating contributed roughly twice as much to Arm's stock performance as earnings growth did. The business did not simply grow into its IPO valuation — the market re-rated it to a materially richer valuation than investors were willing to pay in September 2023, even after accounting for that growth. This reframes the original 11-15% IPO premium: in hindsight it was conservative relative to where the market would ultimately price Arm, but it also means today's shares carry meaningfully more re-rating risk than the IPO price did, since a large share of the current valuation now depends on the AI/data-center narrative continuing to be believed at an even higher multiple than IPO investors paid.
A42: Valuation Evolution: IPO vs. Current
A43: Current price as of August 10, 2026; current balance sheet as of FY2026 year-end (March 31, 2026)
A45: Metric | B45: IPO (Sep 2023) | C45: Current (Aug 2026) | D45: Change
A46: Share Price | B46: 51 | C46: 272.21 | D46: =C46/B46 -> 5.337451
A47: Diluted Shares Outstanding (mm) | B47: 1026.0549 | C47: 1064.0553 | D47: =C47/B47 -> 1.0370354
A48: Market Cap / Equity Value | B48: =B46*B47 -> 52328.798 | C48: =C46*C47 -> 289646.48 | D48: =C48/B48 -> 5.5351258
A49: Net Cash + ST Investments | B49: 2215 | C49: 3601 | D49: =C49/B49 -> 1.6257336
A50: Enterprise Value | B50: =B48-B49 -> 50113.798 | C50: =C48-C49 -> 286045.48 | D50: =C50/B50 -> 5.7079186
A52: Revenue (FY23A / FY26A) | B52: 2679 | C52: 4920 | D52: =C52/B52 -> 1.8365062
A53: Diluted EPS, GAAP (FY23A / FY26A) | B53: 0.51 | C53: 0.85 | D53: =C53/B53 -> 1.6666667
A55: EV / Revenue | B55: =B50/B52 -> 18.706158 | C55: =C50/C52 -> 58.139325 | D55: =C55/B55 -> 3.1080313
A56: P / E | B56: =B46/B53 -> 100 | C56: =C46/C53 -> 320.24706 | D56: =C56/B56 -> 3.2024706
A59: Return Decomposition (P/E basis)
A60: Total Price Return | B60: =C46/B46 -> 5.337451
...

Sheet Strategy & Risks
A1: Arm Holdings — Strategic Drivers & Risk Framework
A3: How the operating thesis connects to the valuation premium
A5: Strategic Growth Drivers
A6: Driver | B6: Evidence | C6: Valuation Impact | D6: Status by FY2026 / Q1 FY2027 | E6: Assessment
A7: Armv9 adoption | B7: Higher-value architecture supports royalty uplift per chip. | C7: Supports premium royalty growth. | D7: Royalty revenue reached $2.61B in FY2026. | E7: Validated
A8: Data center / cloud | B8: Energy efficiency increasingly valuable for AI workloads. | C8: Expands TAM beyond mobile. | D8: Q1 FY2027 data-center demand remained strong. | E8: Validated / ongoing
A9: License growth | B9: Large high-value agreements expand future royalty base. | C9: Creates backlog and future royalty optionality. | D9: License revenue reached $2.31B in FY2026. | E9: Validated
A10: Automotive / edge | B10: Broader architecture penetration outside smartphones. | C10: Diversifies end-market exposure. | D10: Strategic growth remains ongoing. | E10: Ongoing
A11: AI infrastructure | B11: Arm CPUs increasingly complement accelerators in inference and cloud. | C11: Supports premium multiple and new products. | D11: New AGI CPU demand reportedly exceeded initial expectations. | E11: Emerging
A12: Ecosystem scale | B12: Massive installed base and software ecosystem create switching friction. | C12: Supports durable pricing power. | D12: 350B+ Arm-based chips shipped to date. | E12: Durable moat
A15: Key Risks
A16: Risk | B16: IPO Relevance | C16: Current Read-Through | D16: Valuation Effect | E16: Severity
A17: Smartphone concentration | B17: Core royalty base was tied heavily to mobile. | C17: Smartphone royalty growth remains a watch item in FY2027. | D17: Limits upside if mature mobile demand weakens. | E17: High
A18: Arm China | B18: Material revenue exposure with limited direct control. | C18: China remains strategically important and geopolitically sensitive. | D18: Warrants risk discount. | E18: High
A19: RISC-V | B19: Open-source architecture can reduce willingness to pay for Arm IP. | C19: Long-run ecosystem threat remains. | D19: Could pressure licensing economics. | E19: Medium-High
A20: Customer bargaining power | B20: Largest customers are sophisticated chip designers. | C20: Cloud customers increasingly design custom silicon. | D20: Can pressure pricing despite expanding Arm use. | E20: Medium
A21: SoftBank control | B21: Very small public float at IPO; SoftBank retained control. | C21: SoftBank still owned ~86.4% as of May 2026. | D21: Governance / supply overhang risk. | E21: High
A22: Valuation sensitivity | B22: IPO already priced at a premium. | C22: Shares remain highly sensitive to guidance and growth expectations. | D22: Multiple compression risk. | E22: High
A23: Execution on own chips | B23: Arm historically licensed IP rather than selling finished CPUs. | C23: New data-center CPU strategy expands opportunity but changes execution risk. | D23: Could increase upside and capital intensity. | E23: Medium-High
A26: Final Strategy View
A27: Arm's premium is best understood as a platform-quality premium rather than a conventional semiconductor multiple. The company combines near-100% gross margins, recurring royalties, an asset-light licensing model, and a dominant architecture ecosystem. The strongest evidence since IPO is the simultaneous expansion of both royalty and license revenue. The most important debate is no longer whether Arm can grow beyond smartphones, but how much of future AI/data-center success is already embedded in the valuation. The principal counterweights are SoftBank control, China exposure, RISC-V, and the risk that market expectations move faster than operating results.

Sheet Executive Summary
A1: Arm Holdings IPO Valuation & Strategy Analysis — Executive Summary
A4: Thesis Question
A5: Was Arm Holdings fairly valued at its September 2023 IPO, and did subsequent growth in royalties, licensing, Armv9, data centers, and AI justify the premium valuation?
A8: Key Findings
A9: 1. | B9: Arm priced at roughly 18.7x FY2023 revenue, about 49% above the six-peer median of 12.6x.
A10: 2. | B10: Core IP/EDA comparables imply about $43 per share and the peer 75th percentile about $45, versus the $51 IPO price.
A11: 3. | B11: The premium was aggressive but defensible: Arm had a recurring royalty stream, near-100% gross margins, dominant mobile architecture share, and credible expansion into cloud and automotive.
A12: 4. | B12: Post-IPO fundamentals materially strengthened: FY2023–FY2026 revenue CAGR was about 22%, license revenue about 32%, royalty revenue about 16%, and net income about 20%.
A13: 5. | B13: The stock's first-day close of $63.59 represented a 24.7% gain from the $51 offer price, showing immediate demand exceeded the allocated IPO price.
A14: 6. | B14: By Q1 FY2027, revenue remained above expectations and data-center demand was strong, but smartphone royalties and valuation sensitivity remained important risks.
A15: 7. | B15: SoftBank's continued control, Arm China, RISC-V, and the execution risk of moving further into finished data-center CPUs remain the major strategic counterweights.
A16: 8. | B16: Overall verdict: premium-priced at IPO, but subsequent operating performance validated much of the growth premium rather than proving the IPO was simply mispriced.
A19: Recommendation / Deal Takeaway
A20: From an IPO pricing perspective, SoftBank captured a strong premium to public comparables while still leaving enough upside for a successful first-day debut. A fair comp-based valuation range was approximately $43–$45 per ADS, suggesting the $51 offer price was aggressive by roughly 11–15%. However, the subsequent acceleration in revenue and Arm's strengthening AI/data-center position show why investors were willing to pay beyond conventional semiconductor multiples. The transaction is therefore best viewed as a successful premium IPO whose long-term justification depends on continued royalty monetization and expansion beyond smartphones.
